2022-01-08 03:57:16,140 -  nornir.core -     INFO -        run() - Running task 'test_templates' with args {} on 3 hosts
2022-01-08 03:57:16,142 - nornir.core.task -    ERROR -      start() - Host 'R1': task 'template_file' failed with traceback:
Traceback (most recent call last):
  File "/usr/local/lib/python3.8/dist-packages/nornir/core/task.py", line 99, in start
    r = self.task(self, **self.params)
  File "/home/imad/.local/lib/python3.8/site-packages/nornir_jinja2/plugins/tasks/template_file.py", line 42, in template_file
    t = env.get_template(template)
  File "/home/imad/.local/lib/python3.8/site-packages/jinja2/environment.py", line 997, in get_template
    return self._load_template(name, globals)
  File "/home/imad/.local/lib/python3.8/site-packages/jinja2/environment.py", line 958, in _load_template
    template = self.loader.load(self, name, self.make_globals(globals))
  File "/home/imad/.local/lib/python3.8/site-packages/jinja2/loaders.py", line 125, in load
    source, filename, uptodate = self.get_source(environment, name)
  File "/home/imad/.local/lib/python3.8/site-packages/jinja2/loaders.py", line 214, in get_source
    raise TemplateNotFound(template)
jinja2.exceptions.TemplateNotFound: ospf.j2

2022-01-08 03:57:16,142 - nornir.core.task -    ERROR -      start() - Host 'R1': task 'test_templates' failed with traceback:
Traceback (most recent call last):
  File "/usr/local/lib/python3.8/dist-packages/nornir/core/task.py", line 99, in start
    r = self.task(self, **self.params)
  File "/home/imad/Nornir-Automation/runbook1.py", line 11, in test_templates
    template = task.run(task=template_file, template="ospf.j2", path="templates")
  File "/usr/local/lib/python3.8/dist-packages/nornir/core/task.py", line 174, in run
    raise NornirSubTaskError(task=run_task, result=r)
nornir.core.exceptions.NornirSubTaskError: Subtask: template_file (failed)


2022-01-08 03:57:16,142 - nornir.core.task -    ERROR -      start() - Host 'R3': task 'template_file' failed with traceback:
Traceback (most recent call last):
  File "/usr/local/lib/python3.8/dist-packages/nornir/core/task.py", line 99, in start
    r = self.task(self, **self.params)
  File "/home/imad/.local/lib/python3.8/site-packages/nornir_jinja2/plugins/tasks/template_file.py", line 42, in template_file
    t = env.get_template(template)
  File "/home/imad/.local/lib/python3.8/site-packages/jinja2/environment.py", line 997, in get_template
    return self._load_template(name, globals)
  File "/home/imad/.local/lib/python3.8/site-packages/jinja2/environment.py", line 958, in _load_template
    template = self.loader.load(self, name, self.make_globals(globals))
  File "/home/imad/.local/lib/python3.8/site-packages/jinja2/loaders.py", line 125, in load
    source, filename, uptodate = self.get_source(environment, name)
  File "/home/imad/.local/lib/python3.8/site-packages/jinja2/loaders.py", line 214, in get_source
    raise TemplateNotFound(template)
jinja2.exceptions.TemplateNotFound: ospf.j2

2022-01-08 03:57:16,143 - nornir.core.task -    ERROR -      start() - Host 'R3': task 'test_templates' failed with traceback:
Traceback (most recent call last):
  File "/usr/local/lib/python3.8/dist-packages/nornir/core/task.py", line 99, in start
    r = self.task(self, **self.params)
  File "/home/imad/Nornir-Automation/runbook1.py", line 11, in test_templates
    template = task.run(task=template_file, template="ospf.j2", path="templates")
  File "/usr/local/lib/python3.8/dist-packages/nornir/core/task.py", line 174, in run
    raise NornirSubTaskError(task=run_task, result=r)
nornir.core.exceptions.NornirSubTaskError: Subtask: template_file (failed)


2022-01-08 03:57:16,143 - nornir.core.task -    ERROR -      start() - Host 'R2': task 'template_file' failed with traceback:
Traceback (most recent call last):
  File "/usr/local/lib/python3.8/dist-packages/nornir/core/task.py", line 99, in start
    r = self.task(self, **self.params)
  File "/home/imad/.local/lib/python3.8/site-packages/nornir_jinja2/plugins/tasks/template_file.py", line 42, in template_file
    t = env.get_template(template)
  File "/home/imad/.local/lib/python3.8/site-packages/jinja2/environment.py", line 997, in get_template
    return self._load_template(name, globals)
  File "/home/imad/.local/lib/python3.8/site-packages/jinja2/environment.py", line 958, in _load_template
    template = self.loader.load(self, name, self.make_globals(globals))
  File "/home/imad/.local/lib/python3.8/site-packages/jinja2/loaders.py", line 125, in load
    source, filename, uptodate = self.get_source(environment, name)
  File "/home/imad/.local/lib/python3.8/site-packages/jinja2/loaders.py", line 214, in get_source
    raise TemplateNotFound(template)
jinja2.exceptions.TemplateNotFound: ospf.j2

2022-01-08 03:57:16,143 - nornir.core.task -    ERROR -      start() - Host 'R2': task 'test_templates' failed with traceback:
Traceback (most recent call last):
  File "/usr/local/lib/python3.8/dist-packages/nornir/core/task.py", line 99, in start
    r = self.task(self, **self.params)
  File "/home/imad/Nornir-Automation/runbook1.py", line 11, in test_templates
    template = task.run(task=template_file, template="ospf.j2", path="templates")
  File "/usr/local/lib/python3.8/dist-packages/nornir/core/task.py", line 174, in run
    raise NornirSubTaskError(task=run_task, result=r)
nornir.core.exceptions.NornirSubTaskError: Subtask: template_file (failed)


2022-01-08 03:57:51,789 -  nornir.core -     INFO -        run() - Running task 'test_templates' with args {} on 3 hosts
2022-01-08 03:57:51,795 - nornir.core.task -    ERROR -      start() - Host 'R1': task 'template_file' failed with traceback:
Traceback (most recent call last):
  File "/usr/local/lib/python3.8/dist-packages/nornir/core/task.py", line 99, in start
    r = self.task(self, **self.params)
  File "/home/imad/.local/lib/python3.8/site-packages/nornir_jinja2/plugins/tasks/template_file.py", line 43, in template_file
    text = t.render(host=task.host, **kwargs)
  File "/home/imad/.local/lib/python3.8/site-packages/jinja2/environment.py", line 1291, in render
    self.environment.handle_exception()
  File "/home/imad/.local/lib/python3.8/site-packages/jinja2/environment.py", line 925, in handle_exception
    raise rewrite_traceback_stack(source=source)
  File "/home/imad/Nornir-Automation/templates/ospf.j2", line 4, in top-level template code
    network {{ n['ip'] }} {{ n['wildcard'] }} area {{ n['area'] }}
jinja2.exceptions.UndefinedError: 'str object' has no attribute 'ip'

2022-01-08 03:57:51,795 - nornir.core.task -    ERROR -      start() - Host 'R1': task 'test_templates' failed with traceback:
Traceback (most recent call last):
  File "/usr/local/lib/python3.8/dist-packages/nornir/core/task.py", line 99, in start
    r = self.task(self, **self.params)
  File "/home/imad/Nornir-Automation/runbook1.py", line 11, in test_templates
    template = task.run(task=template_file, template="ospf.j2", path="/home/imad/Nornir-Automation/templates")
  File "/usr/local/lib/python3.8/dist-packages/nornir/core/task.py", line 174, in run
    raise NornirSubTaskError(task=run_task, result=r)
nornir.core.exceptions.NornirSubTaskError: Subtask: template_file (failed)


2022-01-08 03:57:51,797 - nornir.core.task -    ERROR -      start() - Host 'R2': task 'template_file' failed with traceback:
Traceback (most recent call last):
  File "/usr/local/lib/python3.8/dist-packages/nornir/core/task.py", line 99, in start
    r = self.task(self, **self.params)
  File "/home/imad/.local/lib/python3.8/site-packages/nornir_jinja2/plugins/tasks/template_file.py", line 43, in template_file
    text = t.render(host=task.host, **kwargs)
  File "/home/imad/.local/lib/python3.8/site-packages/jinja2/environment.py", line 1291, in render
    self.environment.handle_exception()
  File "/home/imad/.local/lib/python3.8/site-packages/jinja2/environment.py", line 925, in handle_exception
    raise rewrite_traceback_stack(source=source)
  File "/home/imad/Nornir-Automation/templates/ospf.j2", line 4, in top-level template code
    network {{ n['ip'] }} {{ n['wildcard'] }} area {{ n['area'] }}
jinja2.exceptions.UndefinedError: 'str object' has no attribute 'ip'

2022-01-08 03:57:51,797 - nornir.core.task -    ERROR -      start() - Host 'R2': task 'test_templates' failed with traceback:
Traceback (most recent call last):
  File "/usr/local/lib/python3.8/dist-packages/nornir/core/task.py", line 99, in start
    r = self.task(self, **self.params)
  File "/home/imad/Nornir-Automation/runbook1.py", line 11, in test_templates
    template = task.run(task=template_file, template="ospf.j2", path="/home/imad/Nornir-Automation/templates")
  File "/usr/local/lib/python3.8/dist-packages/nornir/core/task.py", line 174, in run
    raise NornirSubTaskError(task=run_task, result=r)
nornir.core.exceptions.NornirSubTaskError: Subtask: template_file (failed)


2022-01-08 03:57:51,800 - nornir.core.task -    ERROR -      start() - Host 'R3': task 'template_file' failed with traceback:
Traceback (most recent call last):
  File "/usr/local/lib/python3.8/dist-packages/nornir/core/task.py", line 99, in start
    r = self.task(self, **self.params)
  File "/home/imad/.local/lib/python3.8/site-packages/nornir_jinja2/plugins/tasks/template_file.py", line 43, in template_file
    text = t.render(host=task.host, **kwargs)
  File "/home/imad/.local/lib/python3.8/site-packages/jinja2/environment.py", line 1291, in render
    self.environment.handle_exception()
  File "/home/imad/.local/lib/python3.8/site-packages/jinja2/environment.py", line 925, in handle_exception
    raise rewrite_traceback_stack(source=source)
  File "/home/imad/Nornir-Automation/templates/ospf.j2", line 4, in top-level template code
    network {{ n['ip'] }} {{ n['wildcard'] }} area {{ n['area'] }}
jinja2.exceptions.UndefinedError: 'str object' has no attribute 'ip'

2022-01-08 03:57:51,800 - nornir.core.task -    ERROR -      start() - Host 'R3': task 'test_templates' failed with traceback:
Traceback (most recent call last):
  File "/usr/local/lib/python3.8/dist-packages/nornir/core/task.py", line 99, in start
    r = self.task(self, **self.params)
  File "/home/imad/Nornir-Automation/runbook1.py", line 11, in test_templates
    template = task.run(task=template_file, template="ospf.j2", path="/home/imad/Nornir-Automation/templates")
  File "/usr/local/lib/python3.8/dist-packages/nornir/core/task.py", line 174, in run
    raise NornirSubTaskError(task=run_task, result=r)
nornir.core.exceptions.NornirSubTaskError: Subtask: template_file (failed)


2022-01-08 03:59:48,062 -  nornir.core -     INFO -        run() - Running task 'test_templates' with args {} on 3 hosts
2022-01-08 04:26:19,138 -  nornir.core -     INFO -        run() - Running task 'test_templates' with args {} on 3 hosts
2022-01-08 04:26:19,140 - nornir.core.task -    ERROR -      start() - Host 'R2': task 'template_file' failed with traceback:
Traceback (most recent call last):
  File "/usr/local/lib/python3.8/dist-packages/nornir/core/task.py", line 99, in start
    r = self.task(self, **self.params)
  File "/home/imad/.local/lib/python3.8/site-packages/nornir_jinja2/plugins/tasks/template_file.py", line 42, in template_file
    t = env.get_template(template)
  File "/home/imad/.local/lib/python3.8/site-packages/jinja2/environment.py", line 997, in get_template
    return self._load_template(name, globals)
  File "/home/imad/.local/lib/python3.8/site-packages/jinja2/environment.py", line 958, in _load_template
    template = self.loader.load(self, name, self.make_globals(globals))
  File "/home/imad/.local/lib/python3.8/site-packages/jinja2/loaders.py", line 125, in load
    source, filename, uptodate = self.get_source(environment, name)
  File "/home/imad/.local/lib/python3.8/site-packages/jinja2/loaders.py", line 214, in get_source
    raise TemplateNotFound(template)
jinja2.exceptions.TemplateNotFound: snmp.j2

2022-01-08 04:26:19,140 - nornir.core.task -    ERROR -      start() - Host 'R2': task 'test_templates' failed with traceback:
Traceback (most recent call last):
  File "/usr/local/lib/python3.8/dist-packages/nornir/core/task.py", line 99, in start
    r = self.task(self, **self.params)
  File "/home/imad/Nornir-Automation/runbook1.py", line 18, in test_templates
    template = task.run(task=template_file, template="snmp.j2", path=f"{task.host.platform}-templates")
  File "/usr/local/lib/python3.8/dist-packages/nornir/core/task.py", line 174, in run
    raise NornirSubTaskError(task=run_task, result=r)
nornir.core.exceptions.NornirSubTaskError: Subtask: template_file (failed)


2022-01-08 04:26:19,140 - nornir.core.task -    ERROR -      start() - Host 'R1': task 'template_file' failed with traceback:
Traceback (most recent call last):
  File "/usr/local/lib/python3.8/dist-packages/nornir/core/task.py", line 99, in start
    r = self.task(self, **self.params)
  File "/home/imad/.local/lib/python3.8/site-packages/nornir_jinja2/plugins/tasks/template_file.py", line 42, in template_file
    t = env.get_template(template)
  File "/home/imad/.local/lib/python3.8/site-packages/jinja2/environment.py", line 997, in get_template
    return self._load_template(name, globals)
  File "/home/imad/.local/lib/python3.8/site-packages/jinja2/environment.py", line 958, in _load_template
    template = self.loader.load(self, name, self.make_globals(globals))
  File "/home/imad/.local/lib/python3.8/site-packages/jinja2/loaders.py", line 125, in load
    source, filename, uptodate = self.get_source(environment, name)
  File "/home/imad/.local/lib/python3.8/site-packages/jinja2/loaders.py", line 214, in get_source
    raise TemplateNotFound(template)
jinja2.exceptions.TemplateNotFound: snmp.j2

2022-01-08 04:26:19,141 - nornir.core.task -    ERROR -      start() - Host 'R1': task 'test_templates' failed with traceback:
Traceback (most recent call last):
  File "/usr/local/lib/python3.8/dist-packages/nornir/core/task.py", line 99, in start
    r = self.task(self, **self.params)
  File "/home/imad/Nornir-Automation/runbook1.py", line 18, in test_templates
    template = task.run(task=template_file, template="snmp.j2", path=f"{task.host.platform}-templates")
  File "/usr/local/lib/python3.8/dist-packages/nornir/core/task.py", line 174, in run
    raise NornirSubTaskError(task=run_task, result=r)
nornir.core.exceptions.NornirSubTaskError: Subtask: template_file (failed)


2022-01-08 04:26:19,141 - nornir.core.task -    ERROR -      start() - Host 'R3': task 'template_file' failed with traceback:
Traceback (most recent call last):
  File "/usr/local/lib/python3.8/dist-packages/nornir/core/task.py", line 99, in start
    r = self.task(self, **self.params)
  File "/home/imad/.local/lib/python3.8/site-packages/nornir_jinja2/plugins/tasks/template_file.py", line 42, in template_file
    t = env.get_template(template)
  File "/home/imad/.local/lib/python3.8/site-packages/jinja2/environment.py", line 997, in get_template
    return self._load_template(name, globals)
  File "/home/imad/.local/lib/python3.8/site-packages/jinja2/environment.py", line 958, in _load_template
    template = self.loader.load(self, name, self.make_globals(globals))
  File "/home/imad/.local/lib/python3.8/site-packages/jinja2/loaders.py", line 125, in load
    source, filename, uptodate = self.get_source(environment, name)
  File "/home/imad/.local/lib/python3.8/site-packages/jinja2/loaders.py", line 214, in get_source
    raise TemplateNotFound(template)
jinja2.exceptions.TemplateNotFound: snmp.j2

2022-01-08 04:26:19,141 - nornir.core.task -    ERROR -      start() - Host 'R3': task 'test_templates' failed with traceback:
Traceback (most recent call last):
  File "/usr/local/lib/python3.8/dist-packages/nornir/core/task.py", line 99, in start
    r = self.task(self, **self.params)
  File "/home/imad/Nornir-Automation/runbook1.py", line 18, in test_templates
    template = task.run(task=template_file, template="snmp.j2", path=f"{task.host.platform}-templates")
  File "/usr/local/lib/python3.8/dist-packages/nornir/core/task.py", line 174, in run
    raise NornirSubTaskError(task=run_task, result=r)
nornir.core.exceptions.NornirSubTaskError: Subtask: template_file (failed)


2022-01-08 04:26:46,266 -  nornir.core -     INFO -        run() - Running task 'test_templates' with args {} on 3 hosts
2022-01-08 04:26:46,268 - nornir.core.task -    ERROR -      start() - Host 'R1': task 'template_file' failed with traceback:
Traceback (most recent call last):
  File "/usr/local/lib/python3.8/dist-packages/nornir/core/task.py", line 99, in start
    r = self.task(self, **self.params)
  File "/home/imad/.local/lib/python3.8/site-packages/nornir_jinja2/plugins/tasks/template_file.py", line 42, in template_file
    t = env.get_template(template)
  File "/home/imad/.local/lib/python3.8/site-packages/jinja2/environment.py", line 997, in get_template
    return self._load_template(name, globals)
  File "/home/imad/.local/lib/python3.8/site-packages/jinja2/environment.py", line 958, in _load_template
    template = self.loader.load(self, name, self.make_globals(globals))
  File "/home/imad/.local/lib/python3.8/site-packages/jinja2/loaders.py", line 125, in load
    source, filename, uptodate = self.get_source(environment, name)
  File "/home/imad/.local/lib/python3.8/site-packages/jinja2/loaders.py", line 214, in get_source
    raise TemplateNotFound(template)
jinja2.exceptions.TemplateNotFound: snmp.j2

2022-01-08 04:26:46,268 - nornir.core.task -    ERROR -      start() - Host 'R1': task 'test_templates' failed with traceback:
Traceback (most recent call last):
  File "/usr/local/lib/python3.8/dist-packages/nornir/core/task.py", line 99, in start
    r = self.task(self, **self.params)
  File "/home/imad/Nornir-Automation/runbook1.py", line 18, in test_templates
    template = task.run(task=template_file, template="snmp.j2", path=f"{task.host.platform}-templates")
  File "/usr/local/lib/python3.8/dist-packages/nornir/core/task.py", line 174, in run
    raise NornirSubTaskError(task=run_task, result=r)
nornir.core.exceptions.NornirSubTaskError: Subtask: template_file (failed)


2022-01-08 04:26:46,268 - nornir.core.task -    ERROR -      start() - Host 'R2': task 'template_file' failed with traceback:
Traceback (most recent call last):
  File "/usr/local/lib/python3.8/dist-packages/nornir/core/task.py", line 99, in start
    r = self.task(self, **self.params)
  File "/home/imad/.local/lib/python3.8/site-packages/nornir_jinja2/plugins/tasks/template_file.py", line 42, in template_file
    t = env.get_template(template)
  File "/home/imad/.local/lib/python3.8/site-packages/jinja2/environment.py", line 997, in get_template
    return self._load_template(name, globals)
  File "/home/imad/.local/lib/python3.8/site-packages/jinja2/environment.py", line 958, in _load_template
    template = self.loader.load(self, name, self.make_globals(globals))
  File "/home/imad/.local/lib/python3.8/site-packages/jinja2/loaders.py", line 125, in load
    source, filename, uptodate = self.get_source(environment, name)
  File "/home/imad/.local/lib/python3.8/site-packages/jinja2/loaders.py", line 214, in get_source
    raise TemplateNotFound(template)
jinja2.exceptions.TemplateNotFound: snmp.j2

2022-01-08 04:26:46,268 - nornir.core.task -    ERROR -      start() - Host 'R2': task 'test_templates' failed with traceback:
Traceback (most recent call last):
  File "/usr/local/lib/python3.8/dist-packages/nornir/core/task.py", line 99, in start
    r = self.task(self, **self.params)
  File "/home/imad/Nornir-Automation/runbook1.py", line 18, in test_templates
    template = task.run(task=template_file, template="snmp.j2", path=f"{task.host.platform}-templates")
  File "/usr/local/lib/python3.8/dist-packages/nornir/core/task.py", line 174, in run
    raise NornirSubTaskError(task=run_task, result=r)
nornir.core.exceptions.NornirSubTaskError: Subtask: template_file (failed)


2022-01-08 04:26:46,269 - nornir.core.task -    ERROR -      start() - Host 'R3': task 'template_file' failed with traceback:
Traceback (most recent call last):
  File "/usr/local/lib/python3.8/dist-packages/nornir/core/task.py", line 99, in start
    r = self.task(self, **self.params)
  File "/home/imad/.local/lib/python3.8/site-packages/nornir_jinja2/plugins/tasks/template_file.py", line 42, in template_file
    t = env.get_template(template)
  File "/home/imad/.local/lib/python3.8/site-packages/jinja2/environment.py", line 997, in get_template
    return self._load_template(name, globals)
  File "/home/imad/.local/lib/python3.8/site-packages/jinja2/environment.py", line 958, in _load_template
    template = self.loader.load(self, name, self.make_globals(globals))
  File "/home/imad/.local/lib/python3.8/site-packages/jinja2/loaders.py", line 125, in load
    source, filename, uptodate = self.get_source(environment, name)
  File "/home/imad/.local/lib/python3.8/site-packages/jinja2/loaders.py", line 214, in get_source
    raise TemplateNotFound(template)
jinja2.exceptions.TemplateNotFound: snmp.j2

2022-01-08 04:26:46,269 - nornir.core.task -    ERROR -      start() - Host 'R3': task 'test_templates' failed with traceback:
Traceback (most recent call last):
  File "/usr/local/lib/python3.8/dist-packages/nornir/core/task.py", line 99, in start
    r = self.task(self, **self.params)
  File "/home/imad/Nornir-Automation/runbook1.py", line 18, in test_templates
    template = task.run(task=template_file, template="snmp.j2", path=f"{task.host.platform}-templates")
  File "/usr/local/lib/python3.8/dist-packages/nornir/core/task.py", line 174, in run
    raise NornirSubTaskError(task=run_task, result=r)
nornir.core.exceptions.NornirSubTaskError: Subtask: template_file (failed)


2022-01-08 04:29:22,635 -  nornir.core -     INFO -        run() - Running task 'test_templates' with args {} on 3 hosts
2022-01-08 04:29:22,636 - nornir.core.task -    ERROR -      start() - Host 'R1': task 'template_file' failed with traceback:
Traceback (most recent call last):
  File "/usr/local/lib/python3.8/dist-packages/nornir/core/task.py", line 99, in start
    r = self.task(self, **self.params)
  File "/home/imad/.local/lib/python3.8/site-packages/nornir_jinja2/plugins/tasks/template_file.py", line 42, in template_file
    t = env.get_template(template)
  File "/home/imad/.local/lib/python3.8/site-packages/jinja2/environment.py", line 997, in get_template
    return self._load_template(name, globals)
  File "/home/imad/.local/lib/python3.8/site-packages/jinja2/environment.py", line 958, in _load_template
    template = self.loader.load(self, name, self.make_globals(globals))
  File "/home/imad/.local/lib/python3.8/site-packages/jinja2/loaders.py", line 125, in load
    source, filename, uptodate = self.get_source(environment, name)
  File "/home/imad/.local/lib/python3.8/site-packages/jinja2/loaders.py", line 214, in get_source
    raise TemplateNotFound(template)
jinja2.exceptions.TemplateNotFound: snmp.j2

2022-01-08 04:29:22,636 - nornir.core.task -    ERROR -      start() - Host 'R1': task 'test_templates' failed with traceback:
Traceback (most recent call last):
  File "/usr/local/lib/python3.8/dist-packages/nornir/core/task.py", line 99, in start
    r = self.task(self, **self.params)
  File "/home/imad/Nornir-Automation/runbook1.py", line 18, in test_templates
    template = task.run(task=template_file, template="snmp.j2", path="-templates")
  File "/usr/local/lib/python3.8/dist-packages/nornir/core/task.py", line 174, in run
    raise NornirSubTaskError(task=run_task, result=r)
nornir.core.exceptions.NornirSubTaskError: Subtask: template_file (failed)


2022-01-08 04:29:22,637 - nornir.core.task -    ERROR -      start() - Host 'R2': task 'template_file' failed with traceback:
Traceback (most recent call last):
  File "/usr/local/lib/python3.8/dist-packages/nornir/core/task.py", line 99, in start
    r = self.task(self, **self.params)
  File "/home/imad/.local/lib/python3.8/site-packages/nornir_jinja2/plugins/tasks/template_file.py", line 42, in template_file
    t = env.get_template(template)
  File "/home/imad/.local/lib/python3.8/site-packages/jinja2/environment.py", line 997, in get_template
    return self._load_template(name, globals)
  File "/home/imad/.local/lib/python3.8/site-packages/jinja2/environment.py", line 958, in _load_template
    template = self.loader.load(self, name, self.make_globals(globals))
  File "/home/imad/.local/lib/python3.8/site-packages/jinja2/loaders.py", line 125, in load
    source, filename, uptodate = self.get_source(environment, name)
  File "/home/imad/.local/lib/python3.8/site-packages/jinja2/loaders.py", line 214, in get_source
    raise TemplateNotFound(template)
jinja2.exceptions.TemplateNotFound: snmp.j2

2022-01-08 04:29:22,637 - nornir.core.task -    ERROR -      start() - Host 'R2': task 'test_templates' failed with traceback:
Traceback (most recent call last):
  File "/usr/local/lib/python3.8/dist-packages/nornir/core/task.py", line 99, in start
    r = self.task(self, **self.params)
  File "/home/imad/Nornir-Automation/runbook1.py", line 18, in test_templates
    template = task.run(task=template_file, template="snmp.j2", path="-templates")
  File "/usr/local/lib/python3.8/dist-packages/nornir/core/task.py", line 174, in run
    raise NornirSubTaskError(task=run_task, result=r)
nornir.core.exceptions.NornirSubTaskError: Subtask: template_file (failed)


2022-01-08 04:29:22,637 - nornir.core.task -    ERROR -      start() - Host 'R3': task 'template_file' failed with traceback:
Traceback (most recent call last):
  File "/usr/local/lib/python3.8/dist-packages/nornir/core/task.py", line 99, in start
    r = self.task(self, **self.params)
  File "/home/imad/.local/lib/python3.8/site-packages/nornir_jinja2/plugins/tasks/template_file.py", line 42, in template_file
    t = env.get_template(template)
  File "/home/imad/.local/lib/python3.8/site-packages/jinja2/environment.py", line 997, in get_template
    return self._load_template(name, globals)
  File "/home/imad/.local/lib/python3.8/site-packages/jinja2/environment.py", line 958, in _load_template
    template = self.loader.load(self, name, self.make_globals(globals))
  File "/home/imad/.local/lib/python3.8/site-packages/jinja2/loaders.py", line 125, in load
    source, filename, uptodate = self.get_source(environment, name)
  File "/home/imad/.local/lib/python3.8/site-packages/jinja2/loaders.py", line 214, in get_source
    raise TemplateNotFound(template)
jinja2.exceptions.TemplateNotFound: snmp.j2

2022-01-08 04:29:22,638 - nornir.core.task -    ERROR -      start() - Host 'R3': task 'test_templates' failed with traceback:
Traceback (most recent call last):
  File "/usr/local/lib/python3.8/dist-packages/nornir/core/task.py", line 99, in start
    r = self.task(self, **self.params)
  File "/home/imad/Nornir-Automation/runbook1.py", line 18, in test_templates
    template = task.run(task=template_file, template="snmp.j2", path="-templates")
  File "/usr/local/lib/python3.8/dist-packages/nornir/core/task.py", line 174, in run
    raise NornirSubTaskError(task=run_task, result=r)
nornir.core.exceptions.NornirSubTaskError: Subtask: template_file (failed)


2022-01-08 04:29:29,571 -  nornir.core -     INFO -        run() - Running task 'test_templates' with args {} on 3 hosts
2022-01-08 04:29:29,572 - nornir.core.task -    ERROR -      start() - Host 'R1': task 'template_file' failed with traceback:
Traceback (most recent call last):
  File "/usr/local/lib/python3.8/dist-packages/nornir/core/task.py", line 99, in start
    r = self.task(self, **self.params)
  File "/home/imad/.local/lib/python3.8/site-packages/nornir_jinja2/plugins/tasks/template_file.py", line 42, in template_file
    t = env.get_template(template)
  File "/home/imad/.local/lib/python3.8/site-packages/jinja2/environment.py", line 997, in get_template
    return self._load_template(name, globals)
  File "/home/imad/.local/lib/python3.8/site-packages/jinja2/environment.py", line 958, in _load_template
    template = self.loader.load(self, name, self.make_globals(globals))
  File "/home/imad/.local/lib/python3.8/site-packages/jinja2/loaders.py", line 125, in load
    source, filename, uptodate = self.get_source(environment, name)
  File "/home/imad/.local/lib/python3.8/site-packages/jinja2/loaders.py", line 214, in get_source
    raise TemplateNotFound(template)
jinja2.exceptions.TemplateNotFound: snmp.j2

2022-01-08 04:29:29,573 - nornir.core.task -    ERROR -      start() - Host 'R1': task 'test_templates' failed with traceback:
Traceback (most recent call last):
  File "/usr/local/lib/python3.8/dist-packages/nornir/core/task.py", line 99, in start
    r = self.task(self, **self.params)
  File "/home/imad/Nornir-Automation/runbook1.py", line 18, in test_templates
    template = task.run(task=template_file, template="snmp.j2", path=f"-templates")
  File "/usr/local/lib/python3.8/dist-packages/nornir/core/task.py", line 174, in run
    raise NornirSubTaskError(task=run_task, result=r)
nornir.core.exceptions.NornirSubTaskError: Subtask: template_file (failed)


2022-01-08 04:29:29,573 - nornir.core.task -    ERROR -      start() - Host 'R2': task 'template_file' failed with traceback:
Traceback (most recent call last):
  File "/usr/local/lib/python3.8/dist-packages/nornir/core/task.py", line 99, in start
    r = self.task(self, **self.params)
  File "/home/imad/.local/lib/python3.8/site-packages/nornir_jinja2/plugins/tasks/template_file.py", line 42, in template_file
    t = env.get_template(template)
  File "/home/imad/.local/lib/python3.8/site-packages/jinja2/environment.py", line 997, in get_template
    return self._load_template(name, globals)
  File "/home/imad/.local/lib/python3.8/site-packages/jinja2/environment.py", line 958, in _load_template
    template = self.loader.load(self, name, self.make_globals(globals))
  File "/home/imad/.local/lib/python3.8/site-packages/jinja2/loaders.py", line 125, in load
    source, filename, uptodate = self.get_source(environment, name)
  File "/home/imad/.local/lib/python3.8/site-packages/jinja2/loaders.py", line 214, in get_source
    raise TemplateNotFound(template)
jinja2.exceptions.TemplateNotFound: snmp.j2

2022-01-08 04:29:29,573 - nornir.core.task -    ERROR -      start() - Host 'R2': task 'test_templates' failed with traceback:
Traceback (most recent call last):
  File "/usr/local/lib/python3.8/dist-packages/nornir/core/task.py", line 99, in start
    r = self.task(self, **self.params)
  File "/home/imad/Nornir-Automation/runbook1.py", line 18, in test_templates
    template = task.run(task=template_file, template="snmp.j2", path=f"-templates")
  File "/usr/local/lib/python3.8/dist-packages/nornir/core/task.py", line 174, in run
    raise NornirSubTaskError(task=run_task, result=r)
nornir.core.exceptions.NornirSubTaskError: Subtask: template_file (failed)


2022-01-08 04:29:29,573 - nornir.core.task -    ERROR -      start() - Host 'R3': task 'template_file' failed with traceback:
Traceback (most recent call last):
  File "/usr/local/lib/python3.8/dist-packages/nornir/core/task.py", line 99, in start
    r = self.task(self, **self.params)
  File "/home/imad/.local/lib/python3.8/site-packages/nornir_jinja2/plugins/tasks/template_file.py", line 42, in template_file
    t = env.get_template(template)
  File "/home/imad/.local/lib/python3.8/site-packages/jinja2/environment.py", line 997, in get_template
    return self._load_template(name, globals)
  File "/home/imad/.local/lib/python3.8/site-packages/jinja2/environment.py", line 958, in _load_template
    template = self.loader.load(self, name, self.make_globals(globals))
  File "/home/imad/.local/lib/python3.8/site-packages/jinja2/loaders.py", line 125, in load
    source, filename, uptodate = self.get_source(environment, name)
  File "/home/imad/.local/lib/python3.8/site-packages/jinja2/loaders.py", line 214, in get_source
    raise TemplateNotFound(template)
jinja2.exceptions.TemplateNotFound: snmp.j2

2022-01-08 04:29:29,573 - nornir.core.task -    ERROR -      start() - Host 'R3': task 'test_templates' failed with traceback:
Traceback (most recent call last):
  File "/usr/local/lib/python3.8/dist-packages/nornir/core/task.py", line 99, in start
    r = self.task(self, **self.params)
  File "/home/imad/Nornir-Automation/runbook1.py", line 18, in test_templates
    template = task.run(task=template_file, template="snmp.j2", path=f"-templates")
  File "/usr/local/lib/python3.8/dist-packages/nornir/core/task.py", line 174, in run
    raise NornirSubTaskError(task=run_task, result=r)
nornir.core.exceptions.NornirSubTaskError: Subtask: template_file (failed)


2022-01-08 04:29:34,995 -  nornir.core -     INFO -        run() - Running task 'test_templates' with args {} on 3 hosts
2022-01-08 04:29:34,996 - nornir.core.task -    ERROR -      start() - Host 'R1': task 'template_file' failed with traceback:
Traceback (most recent call last):
  File "/usr/local/lib/python3.8/dist-packages/nornir/core/task.py", line 99, in start
    r = self.task(self, **self.params)
  File "/home/imad/.local/lib/python3.8/site-packages/nornir_jinja2/plugins/tasks/template_file.py", line 42, in template_file
    t = env.get_template(template)
  File "/home/imad/.local/lib/python3.8/site-packages/jinja2/environment.py", line 997, in get_template
    return self._load_template(name, globals)
  File "/home/imad/.local/lib/python3.8/site-packages/jinja2/environment.py", line 958, in _load_template
    template = self.loader.load(self, name, self.make_globals(globals))
  File "/home/imad/.local/lib/python3.8/site-packages/jinja2/loaders.py", line 125, in load
    source, filename, uptodate = self.get_source(environment, name)
  File "/home/imad/.local/lib/python3.8/site-packages/jinja2/loaders.py", line 214, in get_source
    raise TemplateNotFound(template)
jinja2.exceptions.TemplateNotFound: snmp.j2

2022-01-08 04:29:34,996 - nornir.core.task -    ERROR -      start() - Host 'R1': task 'test_templates' failed with traceback:
Traceback (most recent call last):
  File "/usr/local/lib/python3.8/dist-packages/nornir/core/task.py", line 99, in start
    r = self.task(self, **self.params)
  File "/home/imad/Nornir-Automation/runbook1.py", line 18, in test_templates
    template = task.run(task=template_file, template="snmp.j2", path=f"{task.host.platform}-templates")
  File "/usr/local/lib/python3.8/dist-packages/nornir/core/task.py", line 174, in run
    raise NornirSubTaskError(task=run_task, result=r)
nornir.core.exceptions.NornirSubTaskError: Subtask: template_file (failed)


2022-01-08 04:29:34,997 - nornir.core.task -    ERROR -      start() - Host 'R2': task 'template_file' failed with traceback:
Traceback (most recent call last):
  File "/usr/local/lib/python3.8/dist-packages/nornir/core/task.py", line 99, in start
    r = self.task(self, **self.params)
  File "/home/imad/.local/lib/python3.8/site-packages/nornir_jinja2/plugins/tasks/template_file.py", line 42, in template_file
    t = env.get_template(template)
  File "/home/imad/.local/lib/python3.8/site-packages/jinja2/environment.py", line 997, in get_template
    return self._load_template(name, globals)
  File "/home/imad/.local/lib/python3.8/site-packages/jinja2/environment.py", line 958, in _load_template
    template = self.loader.load(self, name, self.make_globals(globals))
  File "/home/imad/.local/lib/python3.8/site-packages/jinja2/loaders.py", line 125, in load
    source, filename, uptodate = self.get_source(environment, name)
  File "/home/imad/.local/lib/python3.8/site-packages/jinja2/loaders.py", line 214, in get_source
    raise TemplateNotFound(template)
jinja2.exceptions.TemplateNotFound: snmp.j2

2022-01-08 04:29:34,997 - nornir.core.task -    ERROR -      start() - Host 'R2': task 'test_templates' failed with traceback:
Traceback (most recent call last):
  File "/usr/local/lib/python3.8/dist-packages/nornir/core/task.py", line 99, in start
    r = self.task(self, **self.params)
  File "/home/imad/Nornir-Automation/runbook1.py", line 18, in test_templates
    template = task.run(task=template_file, template="snmp.j2", path=f"{task.host.platform}-templates")
  File "/usr/local/lib/python3.8/dist-packages/nornir/core/task.py", line 174, in run
    raise NornirSubTaskError(task=run_task, result=r)
nornir.core.exceptions.NornirSubTaskError: Subtask: template_file (failed)


2022-01-08 04:29:34,997 - nornir.core.task -    ERROR -      start() - Host 'R3': task 'template_file' failed with traceback:
Traceback (most recent call last):
  File "/usr/local/lib/python3.8/dist-packages/nornir/core/task.py", line 99, in start
    r = self.task(self, **self.params)
  File "/home/imad/.local/lib/python3.8/site-packages/nornir_jinja2/plugins/tasks/template_file.py", line 42, in template_file
    t = env.get_template(template)
  File "/home/imad/.local/lib/python3.8/site-packages/jinja2/environment.py", line 997, in get_template
    return self._load_template(name, globals)
  File "/home/imad/.local/lib/python3.8/site-packages/jinja2/environment.py", line 958, in _load_template
    template = self.loader.load(self, name, self.make_globals(globals))
  File "/home/imad/.local/lib/python3.8/site-packages/jinja2/loaders.py", line 125, in load
    source, filename, uptodate = self.get_source(environment, name)
  File "/home/imad/.local/lib/python3.8/site-packages/jinja2/loaders.py", line 214, in get_source
    raise TemplateNotFound(template)
jinja2.exceptions.TemplateNotFound: snmp.j2

2022-01-08 04:29:34,997 - nornir.core.task -    ERROR -      start() - Host 'R3': task 'test_templates' failed with traceback:
Traceback (most recent call last):
  File "/usr/local/lib/python3.8/dist-packages/nornir/core/task.py", line 99, in start
    r = self.task(self, **self.params)
  File "/home/imad/Nornir-Automation/runbook1.py", line 18, in test_templates
    template = task.run(task=template_file, template="snmp.j2", path=f"{task.host.platform}-templates")
  File "/usr/local/lib/python3.8/dist-packages/nornir/core/task.py", line 174, in run
    raise NornirSubTaskError(task=run_task, result=r)
nornir.core.exceptions.NornirSubTaskError: Subtask: template_file (failed)


2022-01-08 04:30:24,869 -  nornir.core -     INFO -        run() - Running task 'test_templates' with args {} on 3 hosts
2022-01-08 04:30:24,874 - nornir.core.task -    ERROR -      start() - Host 'R1': task 'template_file' failed with traceback:
Traceback (most recent call last):
  File "/usr/local/lib/python3.8/dist-packages/nornir/core/task.py", line 99, in start
    r = self.task(self, **self.params)
  File "/home/imad/.local/lib/python3.8/site-packages/nornir_jinja2/plugins/tasks/template_file.py", line 43, in template_file
    text = t.render(host=task.host, **kwargs)
  File "/home/imad/.local/lib/python3.8/site-packages/jinja2/environment.py", line 1291, in render
    self.environment.handle_exception()
  File "/home/imad/.local/lib/python3.8/site-packages/jinja2/environment.py", line 925, in handle_exception
    raise rewrite_traceback_stack(source=source)
  File "/home/imad/Nornir-Automation/templates/snmp.j2", line 1, in top-level template code
    snmp-server community {{ host.facts.snmp.snmp_community }}
  File "/home/imad/.local/lib/python3.8/site-packages/jinja2/environment.py", line 474, in getattr
    return getattr(obj, attribute)
jinja2.exceptions.UndefinedError: 'nornir.core.inventory.Host object' has no attribute 'facts'

2022-01-08 04:30:24,874 - nornir.core.task -    ERROR -      start() - Host 'R2': task 'template_file' failed with traceback:
Traceback (most recent call last):
  File "/usr/local/lib/python3.8/dist-packages/nornir/core/task.py", line 99, in start
    r = self.task(self, **self.params)
  File "/home/imad/.local/lib/python3.8/site-packages/nornir_jinja2/plugins/tasks/template_file.py", line 43, in template_file
    text = t.render(host=task.host, **kwargs)
  File "/home/imad/.local/lib/python3.8/site-packages/jinja2/environment.py", line 1291, in render
    self.environment.handle_exception()
  File "/home/imad/.local/lib/python3.8/site-packages/jinja2/environment.py", line 925, in handle_exception
    raise rewrite_traceback_stack(source=source)
  File "/home/imad/Nornir-Automation/templates/snmp.j2", line 1, in top-level template code
    snmp-server community {{ host.facts.snmp.snmp_community }}
  File "/home/imad/.local/lib/python3.8/site-packages/jinja2/environment.py", line 474, in getattr
    return getattr(obj, attribute)
jinja2.exceptions.UndefinedError: 'nornir.core.inventory.Host object' has no attribute 'facts'

2022-01-08 04:30:24,875 - nornir.core.task -    ERROR -      start() - Host 'R2': task 'test_templates' failed with traceback:
Traceback (most recent call last):
  File "/usr/local/lib/python3.8/dist-packages/nornir/core/task.py", line 99, in start
    r = self.task(self, **self.params)
  File "/home/imad/Nornir-Automation/runbook1.py", line 18, in test_templates
    template = task.run(task=template_file, template="snmp.j2", path=f"/home/imad/Nornir-Automation/templates")
  File "/usr/local/lib/python3.8/dist-packages/nornir/core/task.py", line 174, in run
    raise NornirSubTaskError(task=run_task, result=r)
nornir.core.exceptions.NornirSubTaskError: Subtask: template_file (failed)


2022-01-08 04:30:24,875 - nornir.core.task -    ERROR -      start() - Host 'R1': task 'test_templates' failed with traceback:
Traceback (most recent call last):
  File "/usr/local/lib/python3.8/dist-packages/nornir/core/task.py", line 99, in start
    r = self.task(self, **self.params)
  File "/home/imad/Nornir-Automation/runbook1.py", line 18, in test_templates
    template = task.run(task=template_file, template="snmp.j2", path=f"/home/imad/Nornir-Automation/templates")
  File "/usr/local/lib/python3.8/dist-packages/nornir/core/task.py", line 174, in run
    raise NornirSubTaskError(task=run_task, result=r)
nornir.core.exceptions.NornirSubTaskError: Subtask: template_file (failed)


2022-01-08 04:30:24,876 - nornir.core.task -    ERROR -      start() - Host 'R3': task 'template_file' failed with traceback:
Traceback (most recent call last):
  File "/usr/local/lib/python3.8/dist-packages/nornir/core/task.py", line 99, in start
    r = self.task(self, **self.params)
  File "/home/imad/.local/lib/python3.8/site-packages/nornir_jinja2/plugins/tasks/template_file.py", line 43, in template_file
    text = t.render(host=task.host, **kwargs)
  File "/home/imad/.local/lib/python3.8/site-packages/jinja2/environment.py", line 1291, in render
    self.environment.handle_exception()
  File "/home/imad/.local/lib/python3.8/site-packages/jinja2/environment.py", line 925, in handle_exception
    raise rewrite_traceback_stack(source=source)
  File "/home/imad/Nornir-Automation/templates/snmp.j2", line 1, in top-level template code
    snmp-server community {{ host.facts.snmp.snmp_community }}
  File "/home/imad/.local/lib/python3.8/site-packages/jinja2/environment.py", line 474, in getattr
    return getattr(obj, attribute)
jinja2.exceptions.UndefinedError: 'nornir.core.inventory.Host object' has no attribute 'facts'

2022-01-08 04:30:24,876 - nornir.core.task -    ERROR -      start() - Host 'R3': task 'test_templates' failed with traceback:
Traceback (most recent call last):
  File "/usr/local/lib/python3.8/dist-packages/nornir/core/task.py", line 99, in start
    r = self.task(self, **self.params)
  File "/home/imad/Nornir-Automation/runbook1.py", line 18, in test_templates
    template = task.run(task=template_file, template="snmp.j2", path=f"/home/imad/Nornir-Automation/templates")
  File "/usr/local/lib/python3.8/dist-packages/nornir/core/task.py", line 174, in run
    raise NornirSubTaskError(task=run_task, result=r)
nornir.core.exceptions.NornirSubTaskError: Subtask: template_file (failed)


2022-01-08 04:30:36,211 -  nornir.core -     INFO -        run() - Running task 'test_templates' with args {} on 3 hosts
2022-01-08 04:30:36,214 - nornir.core.task -    ERROR -      start() - Host 'R1': task 'template_file' failed with traceback:
Traceback (most recent call last):
  File "/usr/local/lib/python3.8/dist-packages/nornir/core/task.py", line 99, in start
    r = self.task(self, **self.params)
  File "/home/imad/.local/lib/python3.8/site-packages/nornir_jinja2/plugins/tasks/template_file.py", line 43, in template_file
    text = t.render(host=task.host, **kwargs)
  File "/home/imad/.local/lib/python3.8/site-packages/jinja2/environment.py", line 1291, in render
    self.environment.handle_exception()
  File "/home/imad/.local/lib/python3.8/site-packages/jinja2/environment.py", line 925, in handle_exception
    raise rewrite_traceback_stack(source=source)
  File "/home/imad/Nornir-Automation/templates/snmp.j2", line 1, in top-level template code
    snmp-server community {{ host.facts.snmp.snmp_community }}
  File "/home/imad/.local/lib/python3.8/site-packages/jinja2/environment.py", line 474, in getattr
    return getattr(obj, attribute)
jinja2.exceptions.UndefinedError: 'nornir.core.inventory.Host object' has no attribute 'facts'

2022-01-08 04:30:36,215 - nornir.core.task -    ERROR -      start() - Host 'R1': task 'test_templates' failed with traceback:
Traceback (most recent call last):
  File "/usr/local/lib/python3.8/dist-packages/nornir/core/task.py", line 99, in start
    r = self.task(self, **self.params)
  File "/home/imad/Nornir-Automation/runbook1.py", line 18, in test_templates
    template = task.run(task=template_file, template="snmp.j2", path="/home/imad/Nornir-Automation/templates")
  File "/usr/local/lib/python3.8/dist-packages/nornir/core/task.py", line 174, in run
    raise NornirSubTaskError(task=run_task, result=r)
nornir.core.exceptions.NornirSubTaskError: Subtask: template_file (failed)


2022-01-08 04:30:36,216 - nornir.core.task -    ERROR -      start() - Host 'R2': task 'template_file' failed with traceback:
Traceback (most recent call last):
  File "/usr/local/lib/python3.8/dist-packages/nornir/core/task.py", line 99, in start
    r = self.task(self, **self.params)
  File "/home/imad/.local/lib/python3.8/site-packages/nornir_jinja2/plugins/tasks/template_file.py", line 43, in template_file
    text = t.render(host=task.host, **kwargs)
  File "/home/imad/.local/lib/python3.8/site-packages/jinja2/environment.py", line 1291, in render
    self.environment.handle_exception()
  File "/home/imad/.local/lib/python3.8/site-packages/jinja2/environment.py", line 925, in handle_exception
    raise rewrite_traceback_stack(source=source)
  File "/home/imad/Nornir-Automation/templates/snmp.j2", line 1, in top-level template code
    snmp-server community {{ host.facts.snmp.snmp_community }}
  File "/home/imad/.local/lib/python3.8/site-packages/jinja2/environment.py", line 474, in getattr
    return getattr(obj, attribute)
jinja2.exceptions.UndefinedError: 'nornir.core.inventory.Host object' has no attribute 'facts'

2022-01-08 04:30:36,216 - nornir.core.task -    ERROR -      start() - Host 'R2': task 'test_templates' failed with traceback:
Traceback (most recent call last):
  File "/usr/local/lib/python3.8/dist-packages/nornir/core/task.py", line 99, in start
    r = self.task(self, **self.params)
  File "/home/imad/Nornir-Automation/runbook1.py", line 18, in test_templates
    template = task.run(task=template_file, template="snmp.j2", path="/home/imad/Nornir-Automation/templates")
  File "/usr/local/lib/python3.8/dist-packages/nornir/core/task.py", line 174, in run
    raise NornirSubTaskError(task=run_task, result=r)
nornir.core.exceptions.NornirSubTaskError: Subtask: template_file (failed)


2022-01-08 04:30:36,217 - nornir.core.task -    ERROR -      start() - Host 'R3': task 'template_file' failed with traceback:
Traceback (most recent call last):
  File "/usr/local/lib/python3.8/dist-packages/nornir/core/task.py", line 99, in start
    r = self.task(self, **self.params)
  File "/home/imad/.local/lib/python3.8/site-packages/nornir_jinja2/plugins/tasks/template_file.py", line 43, in template_file
    text = t.render(host=task.host, **kwargs)
  File "/home/imad/.local/lib/python3.8/site-packages/jinja2/environment.py", line 1291, in render
    self.environment.handle_exception()
  File "/home/imad/.local/lib/python3.8/site-packages/jinja2/environment.py", line 925, in handle_exception
    raise rewrite_traceback_stack(source=source)
  File "/home/imad/Nornir-Automation/templates/snmp.j2", line 1, in top-level template code
    snmp-server community {{ host.facts.snmp.snmp_community }}
  File "/home/imad/.local/lib/python3.8/site-packages/jinja2/environment.py", line 474, in getattr
    return getattr(obj, attribute)
jinja2.exceptions.UndefinedError: 'nornir.core.inventory.Host object' has no attribute 'facts'

2022-01-08 04:30:36,217 - nornir.core.task -    ERROR -      start() - Host 'R3': task 'test_templates' failed with traceback:
Traceback (most recent call last):
  File "/usr/local/lib/python3.8/dist-packages/nornir/core/task.py", line 99, in start
    r = self.task(self, **self.params)
  File "/home/imad/Nornir-Automation/runbook1.py", line 18, in test_templates
    template = task.run(task=template_file, template="snmp.j2", path="/home/imad/Nornir-Automation/templates")
  File "/usr/local/lib/python3.8/dist-packages/nornir/core/task.py", line 174, in run
    raise NornirSubTaskError(task=run_task, result=r)
nornir.core.exceptions.NornirSubTaskError: Subtask: template_file (failed)


2022-01-08 04:31:27,717 -  nornir.core -     INFO -        run() - Running task 'test_templates' with args {} on 3 hosts
2022-01-08 04:31:27,720 - nornir.core.task -    ERROR -      start() - Host 'R1': task 'template_file' failed with traceback:
Traceback (most recent call last):
  File "/usr/local/lib/python3.8/dist-packages/nornir/core/task.py", line 99, in start
    r = self.task(self, **self.params)
  File "/home/imad/.local/lib/python3.8/site-packages/nornir_jinja2/plugins/tasks/template_file.py", line 43, in template_file
    text = t.render(host=task.host, **kwargs)
  File "/home/imad/.local/lib/python3.8/site-packages/jinja2/environment.py", line 1291, in render
    self.environment.handle_exception()
  File "/home/imad/.local/lib/python3.8/site-packages/jinja2/environment.py", line 925, in handle_exception
    raise rewrite_traceback_stack(source=source)
  File "/home/imad/Nornir-Automation/templates/snmp.j2", line 1, in top-level template code
    snmp-server community {{ host.facts.snmp.snmp_community }}
  File "/home/imad/.local/lib/python3.8/site-packages/jinja2/environment.py", line 474, in getattr
    return getattr(obj, attribute)
jinja2.exceptions.UndefinedError: 'nornir.core.inventory.Host object' has no attribute 'facts'

2022-01-08 04:31:27,721 - nornir.core.task -    ERROR -      start() - Host 'R1': task 'test_templates' failed with traceback:
Traceback (most recent call last):
  File "/usr/local/lib/python3.8/dist-packages/nornir/core/task.py", line 99, in start
    r = self.task(self, **self.params)
  File "/home/imad/Nornir-Automation/runbook1.py", line 18, in test_templates
    template = task.run(task=template_file, template="snmp.j2", path="/home/imad/Nornir-Automation/templates")
  File "/usr/local/lib/python3.8/dist-packages/nornir/core/task.py", line 174, in run
    raise NornirSubTaskError(task=run_task, result=r)
nornir.core.exceptions.NornirSubTaskError: Subtask: template_file (failed)


2022-01-08 04:31:27,721 - nornir.core.task -    ERROR -      start() - Host 'R2': task 'template_file' failed with traceback:
Traceback (most recent call last):
  File "/usr/local/lib/python3.8/dist-packages/nornir/core/task.py", line 99, in start
    r = self.task(self, **self.params)
  File "/home/imad/.local/lib/python3.8/site-packages/nornir_jinja2/plugins/tasks/template_file.py", line 43, in template_file
    text = t.render(host=task.host, **kwargs)
  File "/home/imad/.local/lib/python3.8/site-packages/jinja2/environment.py", line 1291, in render
    self.environment.handle_exception()
  File "/home/imad/.local/lib/python3.8/site-packages/jinja2/environment.py", line 925, in handle_exception
    raise rewrite_traceback_stack(source=source)
  File "/home/imad/Nornir-Automation/templates/snmp.j2", line 1, in top-level template code
    snmp-server community {{ host.facts.snmp.snmp_community }}
  File "/home/imad/.local/lib/python3.8/site-packages/jinja2/environment.py", line 474, in getattr
    return getattr(obj, attribute)
jinja2.exceptions.UndefinedError: 'nornir.core.inventory.Host object' has no attribute 'facts'

2022-01-08 04:31:27,722 - nornir.core.task -    ERROR -      start() - Host 'R2': task 'test_templates' failed with traceback:
Traceback (most recent call last):
  File "/usr/local/lib/python3.8/dist-packages/nornir/core/task.py", line 99, in start
    r = self.task(self, **self.params)
  File "/home/imad/Nornir-Automation/runbook1.py", line 18, in test_templates
    template = task.run(task=template_file, template="snmp.j2", path="/home/imad/Nornir-Automation/templates")
  File "/usr/local/lib/python3.8/dist-packages/nornir/core/task.py", line 174, in run
    raise NornirSubTaskError(task=run_task, result=r)
nornir.core.exceptions.NornirSubTaskError: Subtask: template_file (failed)


2022-01-08 04:31:27,723 - nornir.core.task -    ERROR -      start() - Host 'R3': task 'template_file' failed with traceback:
Traceback (most recent call last):
  File "/usr/local/lib/python3.8/dist-packages/nornir/core/task.py", line 99, in start
    r = self.task(self, **self.params)
  File "/home/imad/.local/lib/python3.8/site-packages/nornir_jinja2/plugins/tasks/template_file.py", line 43, in template_file
    text = t.render(host=task.host, **kwargs)
  File "/home/imad/.local/lib/python3.8/site-packages/jinja2/environment.py", line 1291, in render
    self.environment.handle_exception()
  File "/home/imad/.local/lib/python3.8/site-packages/jinja2/environment.py", line 925, in handle_exception
    raise rewrite_traceback_stack(source=source)
  File "/home/imad/Nornir-Automation/templates/snmp.j2", line 1, in top-level template code
    snmp-server community {{ host.facts.snmp.snmp_community }}
  File "/home/imad/.local/lib/python3.8/site-packages/jinja2/environment.py", line 474, in getattr
    return getattr(obj, attribute)
jinja2.exceptions.UndefinedError: 'nornir.core.inventory.Host object' has no attribute 'facts'

2022-01-08 04:31:27,723 - nornir.core.task -    ERROR -      start() - Host 'R3': task 'test_templates' failed with traceback:
Traceback (most recent call last):
  File "/usr/local/lib/python3.8/dist-packages/nornir/core/task.py", line 99, in start
    r = self.task(self, **self.params)
  File "/home/imad/Nornir-Automation/runbook1.py", line 18, in test_templates
    template = task.run(task=template_file, template="snmp.j2", path="/home/imad/Nornir-Automation/templates")
  File "/usr/local/lib/python3.8/dist-packages/nornir/core/task.py", line 174, in run
    raise NornirSubTaskError(task=run_task, result=r)
nornir.core.exceptions.NornirSubTaskError: Subtask: template_file (failed)


2022-01-08 04:31:34,714 -  nornir.core -     INFO -        run() - Running task 'test_templates' with args {} on 3 hosts
2022-01-08 04:31:34,718 - nornir.core.task -    ERROR -      start() - Host 'R1': task 'template_file' failed with traceback:
Traceback (most recent call last):
  File "/usr/local/lib/python3.8/dist-packages/nornir/core/task.py", line 99, in start
    r = self.task(self, **self.params)
  File "/home/imad/.local/lib/python3.8/site-packages/nornir_jinja2/plugins/tasks/template_file.py", line 43, in template_file
    text = t.render(host=task.host, **kwargs)
  File "/home/imad/.local/lib/python3.8/site-packages/jinja2/environment.py", line 1291, in render
    self.environment.handle_exception()
  File "/home/imad/.local/lib/python3.8/site-packages/jinja2/environment.py", line 925, in handle_exception
    raise rewrite_traceback_stack(source=source)
  File "/home/imad/Nornir-Automation/templates/snmp.j2", line 1, in top-level template code
    snmp-server community {{ host.snmp.snmp_community }}
  File "/home/imad/.local/lib/python3.8/site-packages/jinja2/environment.py", line 474, in getattr
    return getattr(obj, attribute)
jinja2.exceptions.UndefinedError: 'nornir.core.inventory.Host object' has no attribute 'snmp'

2022-01-08 04:31:34,718 - nornir.core.task -    ERROR -      start() - Host 'R1': task 'test_templates' failed with traceback:
Traceback (most recent call last):
  File "/usr/local/lib/python3.8/dist-packages/nornir/core/task.py", line 99, in start
    r = self.task(self, **self.params)
  File "/home/imad/Nornir-Automation/runbook1.py", line 18, in test_templates
    template = task.run(task=template_file, template="snmp.j2", path="/home/imad/Nornir-Automation/templates")
  File "/usr/local/lib/python3.8/dist-packages/nornir/core/task.py", line 174, in run
    raise NornirSubTaskError(task=run_task, result=r)
nornir.core.exceptions.NornirSubTaskError: Subtask: template_file (failed)


2022-01-08 04:31:34,718 - nornir.core.task -    ERROR -      start() - Host 'R2': task 'template_file' failed with traceback:
Traceback (most recent call last):
  File "/usr/local/lib/python3.8/dist-packages/nornir/core/task.py", line 99, in start
    r = self.task(self, **self.params)
  File "/home/imad/.local/lib/python3.8/site-packages/nornir_jinja2/plugins/tasks/template_file.py", line 43, in template_file
    text = t.render(host=task.host, **kwargs)
  File "/home/imad/.local/lib/python3.8/site-packages/jinja2/environment.py", line 1291, in render
    self.environment.handle_exception()
  File "/home/imad/.local/lib/python3.8/site-packages/jinja2/environment.py", line 925, in handle_exception
    raise rewrite_traceback_stack(source=source)
  File "/home/imad/Nornir-Automation/templates/snmp.j2", line 1, in top-level template code
    snmp-server community {{ host.snmp.snmp_community }}
  File "/home/imad/.local/lib/python3.8/site-packages/jinja2/environment.py", line 474, in getattr
    return getattr(obj, attribute)
jinja2.exceptions.UndefinedError: 'nornir.core.inventory.Host object' has no attribute 'snmp'

2022-01-08 04:31:34,719 - nornir.core.task -    ERROR -      start() - Host 'R2': task 'test_templates' failed with traceback:
Traceback (most recent call last):
  File "/usr/local/lib/python3.8/dist-packages/nornir/core/task.py", line 99, in start
    r = self.task(self, **self.params)
  File "/home/imad/Nornir-Automation/runbook1.py", line 18, in test_templates
    template = task.run(task=template_file, template="snmp.j2", path="/home/imad/Nornir-Automation/templates")
  File "/usr/local/lib/python3.8/dist-packages/nornir/core/task.py", line 174, in run
    raise NornirSubTaskError(task=run_task, result=r)
nornir.core.exceptions.NornirSubTaskError: Subtask: template_file (failed)


2022-01-08 04:31:34,720 - nornir.core.task -    ERROR -      start() - Host 'R3': task 'template_file' failed with traceback:
Traceback (most recent call last):
  File "/usr/local/lib/python3.8/dist-packages/nornir/core/task.py", line 99, in start
    r = self.task(self, **self.params)
  File "/home/imad/.local/lib/python3.8/site-packages/nornir_jinja2/plugins/tasks/template_file.py", line 43, in template_file
    text = t.render(host=task.host, **kwargs)
  File "/home/imad/.local/lib/python3.8/site-packages/jinja2/environment.py", line 1291, in render
    self.environment.handle_exception()
  File "/home/imad/.local/lib/python3.8/site-packages/jinja2/environment.py", line 925, in handle_exception
    raise rewrite_traceback_stack(source=source)
  File "/home/imad/Nornir-Automation/templates/snmp.j2", line 1, in top-level template code
    snmp-server community {{ host.snmp.snmp_community }}
  File "/home/imad/.local/lib/python3.8/site-packages/jinja2/environment.py", line 474, in getattr
    return getattr(obj, attribute)
jinja2.exceptions.UndefinedError: 'nornir.core.inventory.Host object' has no attribute 'snmp'

2022-01-08 04:31:34,720 - nornir.core.task -    ERROR -      start() - Host 'R3': task 'test_templates' failed with traceback:
Traceback (most recent call last):
  File "/usr/local/lib/python3.8/dist-packages/nornir/core/task.py", line 99, in start
    r = self.task(self, **self.params)
  File "/home/imad/Nornir-Automation/runbook1.py", line 18, in test_templates
    template = task.run(task=template_file, template="snmp.j2", path="/home/imad/Nornir-Automation/templates")
  File "/usr/local/lib/python3.8/dist-packages/nornir/core/task.py", line 174, in run
    raise NornirSubTaskError(task=run_task, result=r)
nornir.core.exceptions.NornirSubTaskError: Subtask: template_file (failed)


2022-01-15 05:32:18,718 -  nornir.core -     INFO -        run() - Running task 'yangtest' with args {} on 1 hosts
2022-01-15 05:32:18,722 - nornir.core.task -    ERROR -      start() - Host 'R5': task 'template_file' failed with traceback:
Traceback (most recent call last):
  File "/usr/local/lib/python3.8/dist-packages/nornir/core/task.py", line 99, in start
    r = self.task(self, **self.params)
  File "/home/imad/.local/lib/python3.8/site-packages/nornir_jinja2/plugins/tasks/template_file.py", line 42, in template_file
    t = env.get_template(template)
  File "/home/imad/.local/lib/python3.8/site-packages/jinja2/environment.py", line 997, in get_template
    return self._load_template(name, globals)
  File "/home/imad/.local/lib/python3.8/site-packages/jinja2/environment.py", line 958, in _load_template
    template = self.loader.load(self, name, self.make_globals(globals))
  File "/home/imad/.local/lib/python3.8/site-packages/jinja2/loaders.py", line 125, in load
    source, filename, uptodate = self.get_source(environment, name)
  File "/home/imad/.local/lib/python3.8/site-packages/jinja2/loaders.py", line 214, in get_source
    raise TemplateNotFound(template)
jinja2.exceptions.TemplateNotFound: netospf.j2

2022-01-15 05:32:18,722 - nornir.core.task -    ERROR -      start() - Host 'R5': task 'yangtest' failed with traceback:
Traceback (most recent call last):
  File "/usr/local/lib/python3.8/dist-packages/nornir/core/task.py", line 99, in start
    r = self.task(self, **self.params)
  File "/home/imad/Nornir-Automation/Net.py", line 10, in yangtest
    templatetoload = task.run (task=template_file, template="netospf.j2" ,
  File "/usr/local/lib/python3.8/dist-packages/nornir/core/task.py", line 174, in run
    raise NornirSubTaskError(task=run_task, result=r)
nornir.core.exceptions.NornirSubTaskError: Subtask: template_file (failed)


2022-01-15 05:35:49,503 -  nornir.core -     INFO -        run() - Running task 'yangtest' with args {} on 1 hosts
2022-01-15 05:35:49,504 - nornir.core.task -    ERROR -      start() - Host 'R5': task 'template_file' failed with traceback:
Traceback (most recent call last):
  File "/usr/local/lib/python3.8/dist-packages/nornir/core/task.py", line 99, in start
    r = self.task(self, **self.params)
  File "/home/imad/.local/lib/python3.8/site-packages/nornir_jinja2/plugins/tasks/template_file.py", line 42, in template_file
    t = env.get_template(template)
  File "/home/imad/.local/lib/python3.8/site-packages/jinja2/environment.py", line 997, in get_template
    return self._load_template(name, globals)
  File "/home/imad/.local/lib/python3.8/site-packages/jinja2/environment.py", line 958, in _load_template
    template = self.loader.load(self, name, self.make_globals(globals))
  File "/home/imad/.local/lib/python3.8/site-packages/jinja2/loaders.py", line 125, in load
    source, filename, uptodate = self.get_source(environment, name)
  File "/home/imad/.local/lib/python3.8/site-packages/jinja2/loaders.py", line 214, in get_source
    raise TemplateNotFound(template)
jinja2.exceptions.TemplateNotFound: netospf.j2

2022-01-15 05:35:49,505 - nornir.core.task -    ERROR -      start() - Host 'R5': task 'yangtest' failed with traceback:
Traceback (most recent call last):
  File "/usr/local/lib/python3.8/dist-packages/nornir/core/task.py", line 99, in start
    r = self.task(self, **self.params)
  File "/home/imad/Nornir-Automation/Net.py", line 10, in yangtest
    templatetoload = task.run (task=template_file, template="netospf.j2" , path="Nornir-Automation/templates")
  File "/usr/local/lib/python3.8/dist-packages/nornir/core/task.py", line 174, in run
    raise NornirSubTaskError(task=run_task, result=r)
nornir.core.exceptions.NornirSubTaskError: Subtask: template_file (failed)


2022-01-15 05:36:00,004 -  nornir.core -     INFO -        run() - Running task 'yangtest' with args {} on 1 hosts
2022-01-15 05:36:00,006 - nornir.core.task -    ERROR -      start() - Host 'R5': task 'template_file' failed with traceback:
Traceback (most recent call last):
  File "/usr/local/lib/python3.8/dist-packages/nornir/core/task.py", line 99, in start
    r = self.task(self, **self.params)
  File "/home/imad/.local/lib/python3.8/site-packages/nornir_jinja2/plugins/tasks/template_file.py", line 42, in template_file
    t = env.get_template(template)
  File "/home/imad/.local/lib/python3.8/site-packages/jinja2/environment.py", line 997, in get_template
    return self._load_template(name, globals)
  File "/home/imad/.local/lib/python3.8/site-packages/jinja2/environment.py", line 958, in _load_template
    template = self.loader.load(self, name, self.make_globals(globals))
  File "/home/imad/.local/lib/python3.8/site-packages/jinja2/loaders.py", line 125, in load
    source, filename, uptodate = self.get_source(environment, name)
  File "/home/imad/.local/lib/python3.8/site-packages/jinja2/loaders.py", line 214, in get_source
    raise TemplateNotFound(template)
jinja2.exceptions.TemplateNotFound: netospf.j2

2022-01-15 05:36:00,006 - nornir.core.task -    ERROR -      start() - Host 'R5': task 'yangtest' failed with traceback:
Traceback (most recent call last):
  File "/usr/local/lib/python3.8/dist-packages/nornir/core/task.py", line 99, in start
    r = self.task(self, **self.params)
  File "/home/imad/Nornir-Automation/Net.py", line 10, in yangtest
    templatetoload = task.run (task=template_file, template="netospf.j2" , path="imad/Nornir-Automation/templates")
  File "/usr/local/lib/python3.8/dist-packages/nornir/core/task.py", line 174, in run
    raise NornirSubTaskError(task=run_task, result=r)
nornir.core.exceptions.NornirSubTaskError: Subtask: template_file (failed)


2022-01-15 05:36:15,889 -  nornir.core -     INFO -        run() - Running task 'yangtest' with args {} on 1 hosts
2022-01-15 05:36:16,322 - nornir.core.task -    ERROR -      start() - Host 'R5': task 'netconf_edit_config' failed with traceback:
Traceback (most recent call last):
  File "/usr/local/lib/python3.8/dist-packages/nornir/core/task.py", line 99, in start
    r = self.task(self, **self.params)
  File "/usr/local/lib/python3.8/dist-packages/nornir_scrapli/tasks/netconf/edit_config.py", line 43, in netconf_edit_config
    scrapli_response = scrapli_conn.edit_config(config=config, target=target)
  File "/usr/local/lib/python3.8/dist-packages/scrapli_netconf/driver/sync_driver.py", line 200, in edit_config
    response = self._pre_edit_config(config=config, target=target)
  File "/usr/local/lib/python3.8/dist-packages/scrapli_netconf/driver/base_driver.py", line 717, in _pre_edit_config
    edit_config_element.insert(1, xml_config)
TypeError: Argument 'element' has incorrect type (expected lxml.etree._Element, got NoneType)

2022-01-15 05:36:16,322 - nornir.core.task -    ERROR -      start() - Host 'R5': task 'yangtest' failed with traceback:
Traceback (most recent call last):
  File "/usr/local/lib/python3.8/dist-packages/nornir/core/task.py", line 99, in start
    r = self.task(self, **self.params)
  File "/home/imad/Nornir-Automation/Net.py", line 12, in yangtest
    task.run(task=netconf_edit_config, target="running" ,config="configuration")
  File "/usr/local/lib/python3.8/dist-packages/nornir/core/task.py", line 174, in run
    raise NornirSubTaskError(task=run_task, result=r)
nornir.core.exceptions.NornirSubTaskError: Subtask: netconf_edit_config (failed)


2022-01-17 05:28:02,278 -  nornir.core -     INFO -        run() - Running task 'get_yang' with args {} on 1 hosts
2022-01-17 05:31:02,513 -  nornir.core -     INFO -        run() - Running task 'get_yang' with args {} on 1 hosts
2022-01-17 05:31:50,724 -  nornir.core -     INFO -        run() - Running task 'configure_yang' with args {} on 1 hosts
2022-01-17 05:31:50,727 - nornir.core.task -    ERROR -      start() - Host 'R5': task 'template_file' failed with traceback:
Traceback (most recent call last):
  File "/usr/local/lib/python3.8/dist-packages/nornir/core/task.py", line 99, in start
    r = self.task(self, **self.params)
  File "/home/imad/.local/lib/python3.8/site-packages/nornir_jinja2/plugins/tasks/template_file.py", line 42, in template_file
    t = env.get_template(template)
  File "/home/imad/.local/lib/python3.8/site-packages/jinja2/environment.py", line 997, in get_template
    return self._load_template(name, globals)
  File "/home/imad/.local/lib/python3.8/site-packages/jinja2/environment.py", line 958, in _load_template
    template = self.loader.load(self, name, self.make_globals(globals))
  File "/home/imad/.local/lib/python3.8/site-packages/jinja2/loaders.py", line 125, in load
    source, filename, uptodate = self.get_source(environment, name)
  File "/home/imad/.local/lib/python3.8/site-packages/jinja2/loaders.py", line 214, in get_source
    raise TemplateNotFound(template)
jinja2.exceptions.TemplateNotFound: enable.j2

2022-01-17 05:31:50,727 - nornir.core.task -    ERROR -      start() - Host 'R5': task 'configure_yang' failed with traceback:
Traceback (most recent call last):
  File "/usr/local/lib/python3.8/dist-packages/nornir/core/task.py", line 99, in start
    r = self.task(self, **self.params)
  File "/home/imad/Nornir-Automation/push_yang_templates.py", line 12, in configure_yang
    template_to_load = task.run(task=template_file, template="enable.j2", path="templates")
  File "/usr/local/lib/python3.8/dist-packages/nornir/core/task.py", line 174, in run
    raise NornirSubTaskError(task=run_task, result=r)
nornir.core.exceptions.NornirSubTaskError: Subtask: template_file (failed)


2022-01-17 05:42:12,937 -  nornir.core -     INFO -        run() - Running task 'configure_yang' with args {} on 1 hosts
2022-01-17 05:42:12,939 - nornir.core.task -    ERROR -      start() - Host 'R5': task 'template_file' failed with traceback:
Traceback (most recent call last):
  File "/usr/local/lib/python3.8/dist-packages/nornir/core/task.py", line 99, in start
    r = self.task(self, **self.params)
  File "/home/imad/.local/lib/python3.8/site-packages/nornir_jinja2/plugins/tasks/template_file.py", line 42, in template_file
    t = env.get_template(template)
  File "/home/imad/.local/lib/python3.8/site-packages/jinja2/environment.py", line 997, in get_template
    return self._load_template(name, globals)
  File "/home/imad/.local/lib/python3.8/site-packages/jinja2/environment.py", line 958, in _load_template
    template = self.loader.load(self, name, self.make_globals(globals))
  File "/home/imad/.local/lib/python3.8/site-packages/jinja2/loaders.py", line 125, in load
    source, filename, uptodate = self.get_source(environment, name)
  File "/home/imad/.local/lib/python3.8/site-packages/jinja2/loaders.py", line 214, in get_source
    raise TemplateNotFound(template)
jinja2.exceptions.TemplateNotFound: router.j2

2022-01-17 05:42:12,942 - nornir.core.task -    ERROR -      start() - Host 'R5': task 'configure_yang' failed with traceback:
Traceback (most recent call last):
  File "/usr/local/lib/python3.8/dist-packages/nornir/core/task.py", line 99, in start
    r = self.task(self, **self.params)
  File "/home/imad/Nornir-Automation/push_yang_templates.py", line 12, in configure_yang
    template_to_load = task.run(task=template_file, template="router.j2", path="templates")
  File "/usr/local/lib/python3.8/dist-packages/nornir/core/task.py", line 174, in run
    raise NornirSubTaskError(task=run_task, result=r)
nornir.core.exceptions.NornirSubTaskError: Subtask: template_file (failed)


